I'm sorry, but an uncaught exception occurred.

While running game code:
  File "game/script.rpy", line 92, in script call
    call resultados from _call_resultados
  File "game/respuesta final.rpy", line 5, in script
    c "y en el puesto de, [respuesta3]"
KeyError: u'respuesta3'

-- Full Traceback ------------------------------------------------------------

Full traceback:
  File "game/script.rpy", line 92, in script call
    call resultados from _call_resultados
  File "game/respuesta final.rpy", line 5, in script
    c "y en el puesto de, [respuesta3]"
  File "C:\game\renpy-6.99.13-sdk\renpy\ast.py", line 643, in execute
    renpy.exports.say(who, what, interact=self.interact, *args, **kwargs)
  File "C:\game\renpy-6.99.13-sdk\renpy\exports.py", line 1175, in say
    who(what, *args, **kwargs)
  File "C:\game\renpy-6.99.13-sdk\renpy\character.py", line 1000, in __call__
    what = what_pattern.replace("[what]", sub(what, translate=translate))
  File "C:\game\renpy-6.99.13-sdk\renpy\character.py", line 982, in sub
    return renpy.substitutions.substitute(s, scope=scope, force=force, translate=translate)[0]
  File "C:\game\renpy-6.99.13-sdk\renpy\substitutions.py", line 242, in substitute
    s = formatter.vformat(s, (), kwargs)
  File "/home/tom/ab/x64lucid-deps/install/lib/python2.7/string.py", line 563, in vformat
  File "/home/tom/ab/x64lucid-deps/install/lib/python2.7/string.py", line 585, in _vformat
  File "/home/tom/ab/x64lucid-deps/install/lib/python2.7/string.py", line 646, in get_field
  File "/home/tom/ab/x64lucid-deps/install/lib/python2.7/string.py", line 605, in get_value
KeyError: u'respuesta3'

Windows-8-6.2.9200
Ren'Py 6.99.14.3135
Entrevista Fallida 1.0
